<sdf version='1.7'>
  <world name='default'>
    <light name='sun' type='directional'>
      <cast_shadows>1</cast_shadows>
      <pose>0 0 10 0 -0 0</pose>
      <diffuse>0.8 0.8 0.8 1</diffuse>
      <specular>0.2 0.2 0.2 1</specular>
      <attenuation>
        <range>1000</range>
        <constant>0.9</constant>
        <linear>0.01</linear>
        <quadratic>0.001</quadratic>
      </attenuation>
      <direction>-0.5 0.1 -0.9</direction>
      <spot>
        <inner_angle>0</inner_angle>
        <outer_angle>0</outer_angle>
        <falloff>0</falloff>
      </spot>
    </light>
    <model name='ground_plane'>
      <static>1</static>
      <link name='link'>
        <collision name='collision'>
          <geometry>
            <plane>
              <normal>0 0 1</normal>
              <size>100 100</size>
            </plane>
          </geometry>
          <surface>
            <contact>
              <collide_bitmask>65535</collide_bitmask>
              <ode/>
            </contact>
            <friction>
              <ode>
                <mu>100</mu>
                <mu2>50</mu2>
              </ode>
              <torsional>
                <ode/>
              </torsional>
            </friction>
            <bounce/>
          </surface>
          <max_contacts>10</max_contacts>
        </collision>
        <visual name='visual'>
          <cast_shadows>0</cast_shadows>
          <geometry>
            <plane>
              <normal>0 0 1</normal>
              <size>100 100</size>
            </plane>
          </geometry>
          <material>
            <script>
              <uri>file://media/materials/scripts/gazebo.material</uri>
              <name>Gazebo/Grey</name>
            </script>
          </material>
        </visual>
        <self_collide>0</self_collide>
        <enable_wind>0</enable_wind>
        <kinematic>0</kinematic>
      </link>
    </model>
    <gravity>0 0 -9.8</gravity>
    <magnetic_field>6e-06 2.3e-05 -4.2e-05</magnetic_field>
    <atmosphere type='adiabatic'/>
    <physics type='ode'>
      <max_step_size>0.001</max_step_size>
      <real_time_factor>1</real_time_factor>
      <real_time_update_rate>1000</real_time_update_rate>
    </physics>
    <scene>
      <ambient>0.4 0.4 0.4 1</ambient>
      <background>0.7 0.7 0.7 1</background>
      <shadows>1</shadows>
    </scene>
    <audio>
      <device>default</device>
    </audio>
    <wind/>
    <spherical_coordinates>
      <surface_model>EARTH_WGS84</surface_model>
      <latitude_deg>0</latitude_deg>
      <longitude_deg>0</longitude_deg>
      <elevation>0</elevation>
      <heading_deg>0</heading_deg>
    </spherical_coordinates>
    <model name='my_bot'>
      <link name='base_link'>
        <inertial>
          <pose>0.1 0 0.116667 0 -0 0</pose>
          <mass>0.6</mass>
          <inertia>
            <ixx>0.00777083</ixx>
            <ixy>0</ixy>
            <ixz>0</ixz>
            <iyy>0.0106875</iyy>
            <iyz>0</iyz>
            <izz>0.0124167</izz>
          </inertia>
        </inertial>
        <collision name='base_link_fixed_joint_lump__chassis_collision'>
          <pose>0.1 0 0.1 0 -0 0</pose>
          <geometry>
            <box>
              <size>0.4 0.3 0.2</size>
            </box>
          </geometry>
          <max_contacts>10</max_contacts>
          <surface>
            <contact>
              <ode/>
            </contact>
            <bounce/>
            <friction>
              <torsional>
                <ode/>
              </torsional>
              <ode/>
            </friction>
          </surface>
        </collision>
        <collision name='base_link_fixed_joint_lump__lazer_frame_collision_1'>
          <pose>0.1 0 0.2 0 -0 0</pose>
          <geometry>
            <cylinder>
              <length>0.25</length>
              <radius>0.2</radius>
            </cylinder>
          </geometry>
          <surface>
            <contact>
              <ode/>
            </contact>
            <friction>
              <ode/>
              <torsional>
                <ode/>
              </torsional>
            </friction>
            <bounce/>
          </surface>
          <max_contacts>10</max_contacts>
        </collision>
        <visual name='base_link_fixed_joint_lump__chassis_visual'>
          <pose>0.1 0 0.1 0 -0 0</pose>
          <geometry>
            <box>
              <size>0.4 0.3 0.2</size>
            </box>
          </geometry>
        </visual>
        <visual name='base_link_fixed_joint_lump__lazer_frame_visual_1'>
          <pose>0.1 0 0.2 0 -0 0</pose>
          <geometry>
            <cylinder>
              <length>0.25</length>
              <radius>0.05</radius>
            </cylinder>
          </geometry>
        </visual>
        <sensor name='laser' type='ray'>
          <visualize>1</visualize>
          <update_rate>10</update_rate>
          <ray>
            <scan>
              <horizontal>
                <samples>360</samples>
                <min_angle>-3.14</min_angle>
                <max_angle>3.14</max_angle>
                <resolution>1</resolution>
              </horizontal>
              <vertical>
                <samples>1</samples>
                <min_angle>0</min_angle>
                <max_angle>0</max_angle>
              </vertical>
            </scan>
            <range>
              <min>0.3</min>
              <max>12</max>
            </range>
          </ray>
          <plugin name='laser_controller' filename='libgazebo_ros_ray_sensor.so'>
            <ros>
              <argument>~/out:=scan</argument>
            </ros>
            <output_type>sensor_msgs/LaserScan</output_type>
            <frame_name>lazer_frame</frame_name>
          </plugin>
          <pose>0.1 0 0.2 0 -0 0</pose>
        </sensor>
        <self_collide>0</self_collide>
        <enable_wind>0</enable_wind>
        <kinematic>0</kinematic>
      </link>
      <joint name='front_left_wheel_joint' type='revolute'>
        <pose relative_to='base_link'>0.23 0.19 0 1.5708 -0 0</pose>
        <parent>base_link</parent>
        <child>front_left_wheel</child>
        <axis>
          <xyz>0 0 1</xyz>
          <limit>
            <lower>-1e+16</lower>
            <upper>1e+16</upper>
          </limit>
          <dynamics>
            <spring_reference>0</spring_reference>
            <spring_stiffness>0</spring_stiffness>
          </dynamics>
        </axis>
      </joint>
      <link name='front_left_wheel'>
        <pose relative_to='front_left_wheel_joint'>0 0 0 0 -0 0</pose>
        <inertial>
          <pose>0 0 0 0 -0 0</pose>
          <mass>0.2</mass>
          <inertia>
            <ixx>0.000541667</ixx>
            <ixy>0</ixy>
            <ixz>0</ixz>
            <iyy>0.000541667</iyy>
            <iyz>0</iyz>
            <izz>0.001</izz>
          </inertia>
        </inertial>
        <collision name='front_left_wheel_collision'>
          <pose>0 0 0 0 -0 0</pose>
          <geometry>
            <cylinder>
              <length>0.05</length>
              <radius>0.1</radius>
            </cylinder>
          </geometry>
          <max_contacts>10</max_contacts>
          <surface>
            <contact>
              <ode/>
            </contact>
            <bounce/>
            <friction>
              <torsional>
                <ode/>
              </torsional>
              <ode/>
            </friction>
          </surface>
        </collision>
        <visual name='front_left_wheel_visual'>
          <pose>0 0 0 0 -0 0</pose>
          <geometry>
            <cylinder>
              <length>0.05</length>
              <radius>0.1</radius>
            </cylinder>
          </geometry>
        </visual>
        <self_collide>0</self_collide>
        <enable_wind>0</enable_wind>
        <kinematic>0</kinematic>
      </link>
      <joint name='front_right_wheel_joint' type='revolute'>
        <pose relative_to='base_link'>0.23 -0.19 0 1.5708 -0 0</pose>
        <parent>base_link</parent>
        <child>front_right_wheel</child>
        <axis>
          <xyz>0 0 -1</xyz>
          <limit>
            <lower>-1e+16</lower>
            <upper>1e+16</upper>
          </limit>
          <dynamics>
            <spring_reference>0</spring_reference>
            <spring_stiffness>0</spring_stiffness>
          </dynamics>
        </axis>
      </joint>
      <link name='front_right_wheel'>
        <pose relative_to='front_right_wheel_joint'>0 0 0 0 -0 0</pose>
        <inertial>
          <pose>0 0 0 0 -0 0</pose>
          <mass>0.2</mass>
          <inertia>
            <ixx>0.000541667</ixx>
            <ixy>0</ixy>
            <ixz>0</ixz>
            <iyy>0.000541667</iyy>
            <iyz>0</iyz>
            <izz>0.001</izz>
          </inertia>
        </inertial>
        <collision name='front_right_wheel_collision'>
          <pose>0 0 0 0 -0 0</pose>
          <geometry>
            <cylinder>
              <length>0.05</length>
              <radius>0.1</radius>
            </cylinder>
          </geometry>
          <max_contacts>10</max_contacts>
          <surface>
            <contact>
              <ode/>
            </contact>
            <bounce/>
            <friction>
              <torsional>
                <ode/>
              </torsional>
              <ode/>
            </friction>
          </surface>
        </collision>
        <visual name='front_right_wheel_visual'>
          <pose>0 0 0 0 -0 0</pose>
          <geometry>
            <cylinder>
              <length>0.05</length>
              <radius>0.1</radius>
            </cylinder>
          </geometry>
        </visual>
        <self_collide>0</self_collide>
        <enable_wind>0</enable_wind>
        <kinematic>0</kinematic>
      </link>
      <joint name='rear_left_wheel_joint' type='revolute'>
        <pose relative_to='base_link'>0 0.19 0 1.5708 -0 0</pose>
        <parent>base_link</parent>
        <child>rear_left_wheel</child>
        <axis>
          <xyz>0 0 1</xyz>
          <limit>
            <lower>-1e+16</lower>
            <upper>1e+16</upper>
          </limit>
          <dynamics>
            <spring_reference>0</spring_reference>
            <spring_stiffness>0</spring_stiffness>
          </dynamics>
        </axis>
      </joint>
      <link name='rear_left_wheel'>
        <pose relative_to='rear_left_wheel_joint'>0 0 0 0 -0 0</pose>
        <inertial>
          <pose>0 0 0 0 -0 0</pose>
          <mass>0.2</mass>
          <inertia>
            <ixx>0.000541667</ixx>
            <ixy>0</ixy>
            <ixz>0</ixz>
            <iyy>0.000541667</iyy>
            <iyz>0</iyz>
            <izz>0.001</izz>
          </inertia>
        </inertial>
        <collision name='rear_left_wheel_collision'>
          <pose>0 0 0 0 -0 0</pose>
          <geometry>
            <cylinder>
              <length>0.05</length>
              <radius>0.1</radius>
            </cylinder>
          </geometry>
          <max_contacts>10</max_contacts>
          <surface>
            <contact>
              <ode/>
            </contact>
            <bounce/>
            <friction>
              <torsional>
                <ode/>
              </torsional>
              <ode/>
            </friction>
          </surface>
        </collision>
        <visual name='rear_left_wheel_visual'>
          <pose>0 0 0 0 -0 0</pose>
          <geometry>
            <cylinder>
              <length>0.05</length>
              <radius>0.1</radius>
            </cylinder>
          </geometry>
        </visual>
        <self_collide>0</self_collide>
        <enable_wind>0</enable_wind>
        <kinematic>0</kinematic>
      </link>
      <joint name='rear_right_wheel_joint' type='revolute'>
        <pose relative_to='base_link'>0 -0.19 0 1.5708 -0 0</pose>
        <parent>base_link</parent>
        <child>rear_right_wheel</child>
        <axis>
          <xyz>0 0 -1</xyz>
          <limit>
            <lower>-1e+16</lower>
            <upper>1e+16</upper>
          </limit>
          <dynamics>
            <spring_reference>0</spring_reference>
            <spring_stiffness>0</spring_stiffness>
          </dynamics>
        </axis>
      </joint>
      <link name='rear_right_wheel'>
        <pose relative_to='rear_right_wheel_joint'>0 0 0 0 -0 0</pose>
        <inertial>
          <pose>0 0 0 0 -0 0</pose>
          <mass>0.2</mass>
          <inertia>
            <ixx>0.000541667</ixx>
            <ixy>0</ixy>
            <ixz>0</ixz>
            <iyy>0.000541667</iyy>
            <iyz>0</iyz>
            <izz>0.001</izz>
          </inertia>
        </inertial>
        <collision name='rear_right_wheel_collision'>
          <pose>0 0 0 0 -0 0</pose>
          <geometry>
            <cylinder>
              <length>0.05</length>
              <radius>0.1</radius>
            </cylinder>
          </geometry>
          <max_contacts>10</max_contacts>
          <surface>
            <contact>
              <ode/>
            </contact>
            <bounce/>
            <friction>
              <torsional>
                <ode/>
              </torsional>
              <ode/>
            </friction>
          </surface>
        </collision>
        <visual name='rear_right_wheel_visual'>
          <pose>0 0 0 0 -0 0</pose>
          <geometry>
            <cylinder>
              <length>0.05</length>
              <radius>0.1</radius>
            </cylinder>
          </geometry>
        </visual>
        <self_collide>0</self_collide>
        <enable_wind>0</enable_wind>
        <kinematic>0</kinematic>
      </link>
      <static>0</static>
      <plugin name='diff_drive_back' filename='libgazebo_ros_diff_drive.so'>
        <left_joint>rear_left_wheel_joint</left_joint>
        <right_joint>rear_right_wheel_joint</right_joint>
        <wheel_separation>0.38</wheel_separation>
        <wheel_diameter>0.2</wheel_diameter>
        <max_wheel_torque>200</max_wheel_torque>
        <max_wheel_acceleration>10.0</max_wheel_acceleration>
        <odometry_frame>odom</odometry_frame>
        <robot_base_frame>base_link</robot_base_frame>
        <publish_odom>1</publish_odom>
        <publish_odom_tf>1</publish_odom_tf>
        <publish_wheel_tf>1</publish_wheel_tf>
        <command_topic>cmd_vel</command_topic>
      </plugin>
      <plugin name='diff_drive_front' filename='libgazebo_ros_diff_drive.so'>
        <left_joint>front_left_wheel_joint</left_joint>
        <right_joint>front_right_wheel_joint</right_joint>
        <wheel_separation>0.38</wheel_separation>
        <wheel_diameter>0.2</wheel_diameter>
        <max_wheel_torque>200</max_wheel_torque>
        <max_wheel_acceleration>10.0</max_wheel_acceleration>
        <odometry_frame>odom</odometry_frame>
        <robot_base_frame>base_link</robot_base_frame>
        <publish_odom>1</publish_odom>
        <publish_odom_tf>1</publish_odom_tf>
        <publish_wheel_tf>1</publish_wheel_tf>
      </plugin>
      <pose>0 0 0 0 -0 0</pose>
    </model>
    <model name='unit_sphere'>
      <pose>1.60158 2.11281 0.5 0 -0 0</pose>
      <link name='link'>
        <inertial>
          <mass>1</mass>
          <inertia>
            <ixx>0.1</ixx>
            <ixy>0</ixy>
            <ixz>0</ixz>
            <iyy>0.1</iyy>
            <iyz>0</iyz>
            <izz>0.1</izz>
          </inertia>
          <pose>0 0 0 0 -0 0</pose>
        </inertial>
        <collision name='collision'>
          <geometry>
            <sphere>
              <radius>0.5</radius>
            </sphere>
          </geometry>
          <max_contacts>10</max_contacts>
          <surface>
            <contact>
              <ode/>
            </contact>
            <bounce/>
            <friction>
              <torsional>
                <ode/>
              </torsional>
              <ode/>
            </friction>
          </surface>
        </collision>
        <visual name='visual'>
          <geometry>
            <sphere>
              <radius>0.5</radius>
            </sphere>
          </geometry>
          <material>
            <script>
              <name>Gazebo/Grey</name>
              <uri>file://media/materials/scripts/gazebo.material</uri>
            </script>
          </material>
        </visual>
        <self_collide>0</self_collide>
        <enable_wind>0</enable_wind>
        <kinematic>0</kinematic>
      </link>
    </model>
    <model name='unit_box'>
      <pose>-2.33601 -5.53195 0.5 0 -0 0</pose>
      <link name='link'>
        <inertial>
          <mass>1</mass>
          <inertia>
            <ixx>0.166667</ixx>
            <ixy>0</ixy>
            <ixz>0</ixz>
            <iyy>0.166667</iyy>
            <iyz>0</iyz>
            <izz>0.166667</izz>
          </inertia>
          <pose>0 0 0 0 -0 0</pose>
        </inertial>
        <collision name='collision'>
          <geometry>
            <box>
              <size>1 1 1</size>
            </box>
          </geometry>
          <max_contacts>10</max_contacts>
          <surface>
            <contact>
              <ode/>
            </contact>
            <bounce/>
            <friction>
              <torsional>
                <ode/>
              </torsional>
              <ode/>
            </friction>
          </surface>
        </collision>
        <visual name='visual'>
          <geometry>
            <box>
              <size>1 1 1</size>
            </box>
          </geometry>
          <material>
            <script>
              <name>Gazebo/Grey</name>
              <uri>file://media/materials/scripts/gazebo.material</uri>
            </script>
          </material>
        </visual>
        <self_collide>0</self_collide>
        <enable_wind>0</enable_wind>
        <kinematic>0</kinematic>
      </link>
    </model>
    <model name='unit_cylinder'>
      <pose>1.2772 -3.68821 0.5 0 -0 0</pose>
      <link name='link'>
        <inertial>
          <mass>1</mass>
          <inertia>
            <ixx>0.145833</ixx>
            <ixy>0</ixy>
            <ixz>0</ixz>
            <iyy>0.145833</iyy>
            <iyz>0</iyz>
            <izz>0.125</izz>
          </inertia>
          <pose>0 0 0 0 -0 0</pose>
        </inertial>
        <collision name='collision'>
          <geometry>
            <cylinder>
              <radius>0.500001</radius>
              <length>0.999999</length>
            </cylinder>
          </geometry>
          <max_contacts>10</max_contacts>
          <surface>
            <contact>
              <ode/>
            </contact>
            <bounce/>
            <friction>
              <torsional>
                <ode/>
              </torsional>
              <ode/>
            </friction>
          </surface>
        </collision>
        <visual name='visual'>
          <geometry>
            <cylinder>
              <radius>0.500001</radius>
              <length>0.999999</length>
            </cylinder>
          </geometry>
          <material>
            <script>
              <name>Gazebo/Grey</name>
              <uri>file://media/materials/scripts/gazebo.material</uri>
            </script>
          </material>
        </visual>
        <self_collide>0</self_collide>
        <enable_wind>0</enable_wind>
        <kinematic>0</kinematic>
      </link>
    </model>
    <state world_name='default'>
      <sim_time>116 129000000</sim_time>
      <real_time>116 868280252</real_time>
      <wall_time>1686416769 212680015</wall_time>
      <iterations>116129</iterations>
      <model name='ground_plane'>
        <pose>0 0 0 0 -0 0</pose>
        <scale>1 1 1</scale>
        <link name='link'>
          <pose>0 0 0 0 -0 0</pose>
          <velocity>0 0 0 0 -0 0</velocity>
          <acceleration>0 0 0 0 -0 0</acceleration>
          <wrench>0 0 0 0 -0 0</wrench>
        </link>
      </model>
      <model name='my_bot'>
        <pose>9.7e-05 -3.7e-05 0.1 -1e-06 -0 0.001363</pose>
        <scale>1 1 1</scale>
        <link name='base_link'>
          <pose>9.7e-05 -3.7e-05 0.1 -1e-06 -0 0.001363</pose>
          <velocity>1e-06 0 -0 0 -0 -2e-06</velocity>
          <acceleration>-0 -1e-06 1e-06 1e-06 -0 5.1e-05</acceleration>
          <wrench>-0 -1e-06 1e-06 0 -0 0</wrench>
        </link>
        <link name='front_left_wheel'>
          <pose>0.229838 0.190276 0.1 1.57079 0.009782 0.001363</pose>
          <velocity>2e-06 0 -0 1.9e-05 1.6e-05 -2e-06</velocity>
          <acceleration>-1.1e-05 3e-06 2e-06 -9.5e-05 -6.7e-05 0.000107</acceleration>
          <wrench>-2e-06 1e-06 0 0 -0 0</wrench>
        </link>
        <link name='front_right_wheel'>
          <pose>0.230356 -0.189724 0.1 1.57081 0.00327 0.001363</pose>
          <velocity>1e-06 -1e-06 -0 -1.5e-05 5e-06 -3e-06</velocity>
          <acceleration>1e-05 5e-06 -0 -2e-06 6.3e-05 0.000109</acceleration>
          <wrench>2e-06 1e-06 -0 0 -0 0</wrench>
        </link>
        <link name='rear_left_wheel'>
          <pose>-0.000161 0.189962 0.1 1.57079 0.000302 0.001363</pose>
          <velocity>1e-06 1e-06 -0 1.5e-05 1.5e-05 -2e-06</velocity>
          <acceleration>-1.1e-05 -5e-06 -0 0 -6.5e-05 0.000107</acceleration>
          <wrench>-2e-06 -1e-06 -0 0 -0 0</wrench>
        </link>
        <link name='rear_right_wheel'>
          <pose>0.000356 -0.190037 0.1 1.57081 -0.009931 0.001363</pose>
          <velocity>1e-06 -0 -0 -1.9e-05 5e-06 -2e-06</velocity>
          <acceleration>1e-05 -3e-06 2e-06 9.5e-05 6.3e-05 0.000106</acceleration>
          <wrench>2e-06 -1e-06 0 0 -0 0</wrench>
        </link>
      </model>
      <model name='unit_box'>
        <pose>-2.33601 -5.53195 0.499995 0 1e-05 0</pose>
        <scale>1 1 1</scale>
        <link name='link'>
          <pose>-2.33601 -5.53195 0.499995 0 1e-05 0</pose>
          <velocity>0 0 0 0 -0 0</velocity>
          <acceleration>0.010615 -0.006191 -9.78231 0.012424 0.021225 1.8e-05</acceleration>
          <wrench>0.010615 -0.006191 -9.78231 0 -0 0</wrench>
        </link>
      </model>
      <model name='unit_cylinder'>
        <pose>1.27658 -3.29019 0.23537 -1.57079 0.000176 0.752271</pose>
        <scale>0.470773 0.470773 3.05374</scale>
        <link name='link'>
          <pose>1.27658 -3.29019 0.23537 -1.57079 0.000176 0.752271</pose>
          <velocity>0 0 0 0 -0 0</velocity>
          <acceleration>2.09462 -2.14821 -7.65179 0.412736 -0.604936 -0.551874</acceleration>
          <wrench>2.09462 -2.14821 -7.65179 0 -0 0</wrench>
        </link>
      </model>
      <model name='unit_sphere'>
        <pose>1.60158 2.11281 0.5 0 -0 0</pose>
        <scale>1 1 1</scale>
        <link name='link'>
          <pose>1.60158 2.11281 0.5 0 -0 0</pose>
          <velocity>0 0 0 0 -0 0</velocity>
          <acceleration>0 0 0 0 -0 0</acceleration>
          <wrench>0 0 0 0 -0 0</wrench>
        </link>
      </model>
      <light name='sun'>
        <pose>0 0 10 0 -0 0</pose>
      </light>
    </state>
    <gui fullscreen='0'>
      <camera name='user_camera'>
        <pose>10.0108 -12.2069 5.78559 0 0.275643 2.35619</pose>
        <view_controller>orbit</view_controller>
        <projection_type>perspective</projection_type>
      </camera>
    </gui>
  </world>
</sdf>
